10.162.135.151 - - [2023-05-03 21:24:45] "GET /api/getAllProjects HTTP/1.1" 200 15897510 0.643207
10.162.135.151 - - [2023-05-03 21:24:56] "GET /api/getAllProjects HTTP/1.1" 200 15897510 0.582592
[2023-05-03 21:42:35,169] ERROR in app: Exception on /api/getAllProjects [GET]
Traceback (most recent call last):
  File "/home/dcy/anaconda3/envs/EDRE3D/lib/python3.8/site-packages/pymysql/connections.py", line 736, in _read_bytes
    data = self._rfile.read(num_bytes)
  File "/home/dcy/anaconda3/envs/EDRE3D/lib/python3.8/socket.py", line 669, in readinto
    return self._sock.recv_into(b)
TimeoutError: [Errno 110] Connection timed out

During handling of the above exception, another exception occurred:

Traceback (most recent call last):
  File "/home/dcy/anaconda3/envs/EDRE3D/lib/python3.8/site-packages/sqlalchemy/engine/base.py", line 1964, in _exec_single_context
    self.dialect.do_execute(
  File "/home/dcy/anaconda3/envs/EDRE3D/lib/python3.8/site-packages/sqlalchemy/engine/default.py", line 748, in do_execute
    cursor.execute(statement, parameters)
  File "/home/dcy/anaconda3/envs/EDRE3D/lib/python3.8/site-packages/pymysql/cursors.py", line 158, in execute
    result = self._query(query)
  File "/home/dcy/anaconda3/envs/EDRE3D/lib/python3.8/site-packages/pymysql/cursors.py", line 325, in _query
    conn.query(q)
  File "/home/dcy/anaconda3/envs/EDRE3D/lib/python3.8/site-packages/pymysql/connections.py", line 549, in query
    self._affected_rows = self._read_query_result(unbuffered=unbuffered)
  File "/home/dcy/anaconda3/envs/EDRE3D/lib/python3.8/site-packages/pymysql/connections.py", line 779, in _read_query_result
    result.read()
  File "/home/dcy/anaconda3/envs/EDRE3D/lib/python3.8/site-packages/pymysql/connections.py", line 1157, in read
    first_packet = self.connection._read_packet()
  File "/home/dcy/anaconda3/envs/EDRE3D/lib/python3.8/site-packages/pymysql/connections.py", line 696, in _read_packet
    packet_header = self._read_bytes(4)
  File "/home/dcy/anaconda3/envs/EDRE3D/lib/python3.8/site-packages/pymysql/connections.py", line 742, in _read_bytes
    raise err.OperationalError(
pymysql.err.OperationalError: (2013, 'Lost connection to MySQL server during query ([Errno 110] Connection timed out)')

The above exception was the direct cause of the following exception:

Traceback (most recent call last):
  File "/home/dcy/anaconda3/envs/EDRE3D/lib/python3.8/site-packages/flask/app.py", line 2528, in wsgi_app
    response = self.full_dispatch_request()
  File "/home/dcy/anaconda3/envs/EDRE3D/lib/python3.8/site-packages/flask/app.py", line 1825, in full_dispatch_request
    rv = self.handle_user_exception(e)
  File "/home/dcy/anaconda3/envs/EDRE3D/lib/python3.8/site-packages/flask_cors/extension.py", line 165, in wrapped_function
    return cors_after_request(app.make_response(f(*args, **kwargs)))
  File "/home/dcy/anaconda3/envs/EDRE3D/lib/python3.8/site-packages/flask/app.py", line 1823, in full_dispatch_request
    rv = self.dispatch_request()
  File "/home/dcy/anaconda3/envs/EDRE3D/lib/python3.8/site-packages/flask/app.py", line 1799, in dispatch_request
    return self.ensure_sync(self.view_functions[rule.endpoint])(**view_args)
  File "/home/dcy/code/EDREserver/app/api/views.py", line 68, in getAllProjects
    projectList = ProjectList.query.all()
  File "/home/dcy/anaconda3/envs/EDRE3D/lib/python3.8/site-packages/sqlalchemy/orm/query.py", line 2697, in all
    return self._iter().all()  # type: ignore
  File "/home/dcy/anaconda3/envs/EDRE3D/lib/python3.8/site-packages/sqlalchemy/orm/query.py", line 2855, in _iter
    result: Union[ScalarResult[_T], Result[_T]] = self.session.execute(
  File "/home/dcy/anaconda3/envs/EDRE3D/lib/python3.8/site-packages/sqlalchemy/orm/session.py", line 2229, in execute
    return self._execute_internal(
  File "/home/dcy/anaconda3/envs/EDRE3D/lib/python3.8/site-packages/sqlalchemy/orm/session.py", line 2124, in _execute_internal
    result: Result[Any] = compile_state_cls.orm_execute_statement(
  File "/home/dcy/anaconda3/envs/EDRE3D/lib/python3.8/site-packages/sqlalchemy/orm/context.py", line 253, in orm_execute_statement
    result = conn.execute(
  File "/home/dcy/anaconda3/envs/EDRE3D/lib/python3.8/site-packages/sqlalchemy/engine/base.py", line 1414, in execute
    return meth(
  File "/home/dcy/anaconda3/envs/EDRE3D/lib/python3.8/site-packages/sqlalchemy/sql/elements.py", line 486, in _execute_on_connection
    return connection._execute_clauseelement(
  File "/home/dcy/anaconda3/envs/EDRE3D/lib/python3.8/site-packages/sqlalchemy/engine/base.py", line 1638, in _execute_clauseelement
    ret = self._execute_context(
  File "/home/dcy/anaconda3/envs/EDRE3D/lib/python3.8/site-packages/sqlalchemy/engine/base.py", line 1842, in _execute_context
    return self._exec_single_context(
  File "/home/dcy/anaconda3/envs/EDRE3D/lib/python3.8/site-packages/sqlalchemy/engine/base.py", line 1983, in _exec_single_context
    self._handle_dbapi_exception(
  File "/home/dcy/anaconda3/envs/EDRE3D/lib/python3.8/site-packages/sqlalchemy/engine/base.py", line 2326, in _handle_dbapi_exception
    raise sqlalchemy_exception.with_traceback(exc_info[2]) from e
  File "/home/dcy/anaconda3/envs/EDRE3D/lib/python3.8/site-packages/sqlalchemy/engine/base.py", line 1964, in _exec_single_context
    self.dialect.do_execute(
  File "/home/dcy/anaconda3/envs/EDRE3D/lib/python3.8/site-packages/sqlalchemy/engine/default.py", line 748, in do_execute
    cursor.execute(statement, parameters)
  File "/home/dcy/anaconda3/envs/EDRE3D/lib/python3.8/site-packages/pymysql/cursors.py", line 158, in execute
    result = self._query(query)
  File "/home/dcy/anaconda3/envs/EDRE3D/lib/python3.8/site-packages/pymysql/cursors.py", line 325, in _query
    conn.query(q)
  File "/home/dcy/anaconda3/envs/EDRE3D/lib/python3.8/site-packages/pymysql/connections.py", line 549, in query
    self._affected_rows = self._read_query_result(unbuffered=unbuffered)
  File "/home/dcy/anaconda3/envs/EDRE3D/lib/python3.8/site-packages/pymysql/connections.py", line 779, in _read_query_result
    result.read()
  File "/home/dcy/anaconda3/envs/EDRE3D/lib/python3.8/site-packages/pymysql/connections.py", line 1157, in read
    first_packet = self.connection._read_packet()
  File "/home/dcy/anaconda3/envs/EDRE3D/lib/python3.8/site-packages/pymysql/connections.py", line 696, in _read_packet
    packet_header = self._read_bytes(4)
  File "/home/dcy/anaconda3/envs/EDRE3D/lib/python3.8/site-packages/pymysql/connections.py", line 742, in _read_bytes
    raise err.OperationalError(
sqlalchemy.exc.OperationalError: (pymysql.err.OperationalError) (2013, 'Lost connection to MySQL server during query ([Errno 110] Connection timed out)')
[SQL: SELECT `projectList`.id AS `projectList_id`, `projectList`.title AS `projectList_title`, `projectList`.`avatarImgPath` AS `projectList_avatarImgPath`, `projectList`.`projectPath` AS `projectList_projectPath`, `projectList`.`imgNum` AS `projectList_imgNum`, `projectList`.`createTime` AS `projectList_createTime`, `projectList`.state AS `projectList_state` 
FROM `projectList`]
(Background on this error at: https://sqlalche.me/e/20/e3q8)
10.162.135.151 - - [2023-05-03 21:42:35] "GET /api/getAllProjects HTTP/1.1" 500 467 947.824801
[2023-05-03 21:42:45,193] ERROR in app: Exception on /api/getAllProjects [GET]
Traceback (most recent call last):
  File "/home/dcy/anaconda3/envs/EDRE3D/lib/python3.8/site-packages/pymysql/connections.py", line 616, in connect
    sock = socket.create_connection(
  File "/home/dcy/anaconda3/envs/EDRE3D/lib/python3.8/socket.py", line 808, in create_connection
    raise err
  File "/home/dcy/anaconda3/envs/EDRE3D/lib/python3.8/socket.py", line 796, in create_connection
    sock.connect(sa)
socket.timeout: timed out

During handling of the above exception, another exception occurred:

Traceback (most recent call last):
  File "/home/dcy/anaconda3/envs/EDRE3D/lib/python3.8/site-packages/sqlalchemy/engine/base.py", line 145, in __init__
    self._dbapi_connection = engine.raw_connection()
  File "/home/dcy/anaconda3/envs/EDRE3D/lib/python3.8/site-packages/sqlalchemy/engine/base.py", line 3275, in raw_connection
    return self.pool.connect()
  File "/home/dcy/anaconda3/envs/EDRE3D/lib/python3.8/site-packages/sqlalchemy/pool/base.py", line 455, in connect
    return _ConnectionFairy._checkout(self)
  File "/home/dcy/anaconda3/envs/EDRE3D/lib/python3.8/site-packages/sqlalchemy/pool/base.py", line 1271, in _checkout
    fairy = _ConnectionRecord.checkout(pool)
  File "/home/dcy/anaconda3/envs/EDRE3D/lib/python3.8/site-packages/sqlalchemy/pool/base.py", line 725, in checkout
    rec._checkin_failed(err, _fairy_was_created=False)
  File "/home/dcy/anaconda3/envs/EDRE3D/lib/python3.8/site-packages/sqlalchemy/util/langhelpers.py", line 147, in __exit__
    raise exc_value.with_traceback(exc_tb)
  File "/home/dcy/anaconda3/envs/EDRE3D/lib/python3.8/site-packages/sqlalchemy/pool/base.py", line 722, in checkout
    dbapi_connection = rec.get_connection()
  File "/home/dcy/anaconda3/envs/EDRE3D/lib/python3.8/site-packages/sqlalchemy/pool/base.py", line 842, in get_connection
    self.__connect()
  File "/home/dcy/anaconda3/envs/EDRE3D/lib/python3.8/site-packages/sqlalchemy/pool/base.py", line 906, in __connect
    pool.logger.debug("Error on connect(): %s", e)
  File "/home/dcy/anaconda3/envs/EDRE3D/lib/python3.8/site-packages/sqlalchemy/util/langhelpers.py", line 147, in __exit__
    raise exc_value.with_traceback(exc_tb)
  File "/home/dcy/anaconda3/envs/EDRE3D/lib/python3.8/site-packages/sqlalchemy/pool/base.py", line 901, in __connect
    self.dbapi_connection = connection = pool._invoke_creator(self)
  File "/home/dcy/anaconda3/envs/EDRE3D/lib/python3.8/site-packages/sqlalchemy/engine/create.py", line 636, in connect
    return dialect.connect(*cargs, **cparams)
  File "/home/dcy/anaconda3/envs/EDRE3D/lib/python3.8/site-packages/sqlalchemy/engine/default.py", line 580, in connect
    return self.loaded_dbapi.connect(*cargs, **cparams)
  File "/home/dcy/anaconda3/envs/EDRE3D/lib/python3.8/site-packages/pymysql/connections.py", line 352, in __init__
    self.connect()
  File "/home/dcy/anaconda3/envs/EDRE3D/lib/python3.8/site-packages/pymysql/connections.py", line 668, in connect
    raise exc
pymysql.err.OperationalError: (2003, "Can't connect to MySQL server on '10.162.220.155' (timed out)")

The above exception was the direct cause of the following exception:

Traceback (most recent call last):
  File "/home/dcy/anaconda3/envs/EDRE3D/lib/python3.8/site-packages/flask/app.py", line 2528, in wsgi_app
    response = self.full_dispatch_request()
  File "/home/dcy/anaconda3/envs/EDRE3D/lib/python3.8/site-packages/flask/app.py", line 1825, in full_dispatch_request
    rv = self.handle_user_exception(e)
  File "/home/dcy/anaconda3/envs/EDRE3D/lib/python3.8/site-packages/flask_cors/extension.py", line 165, in wrapped_function
    return cors_after_request(app.make_response(f(*args, **kwargs)))
  File "/home/dcy/anaconda3/envs/EDRE3D/lib/python3.8/site-packages/flask/app.py", line 1823, in full_dispatch_request
    rv = self.dispatch_request()
  File "/home/dcy/anaconda3/envs/EDRE3D/lib/python3.8/site-packages/flask/app.py", line 1799, in dispatch_request
    return self.ensure_sync(self.view_functions[rule.endpoint])(**view_args)
  File "/home/dcy/code/EDREserver/app/api/views.py", line 68, in getAllProjects
    projectList = ProjectList.query.all()
  File "/home/dcy/anaconda3/envs/EDRE3D/lib/python3.8/site-packages/sqlalchemy/orm/query.py", line 2697, in all
    return self._iter().all()  # type: ignore
  File "/home/dcy/anaconda3/envs/EDRE3D/lib/python3.8/site-packages/sqlalchemy/orm/query.py", line 2855, in _iter
    result: Union[ScalarResult[_T], Result[_T]] = self.session.execute(
  File "/home/dcy/anaconda3/envs/EDRE3D/lib/python3.8/site-packages/sqlalchemy/orm/session.py", line 2229, in execute
    return self._execute_internal(
  File "/home/dcy/anaconda3/envs/EDRE3D/lib/python3.8/site-packages/sqlalchemy/orm/session.py", line 2114, in _execute_internal
    conn = self._connection_for_bind(bind)
  File "/home/dcy/anaconda3/envs/EDRE3D/lib/python3.8/site-packages/sqlalchemy/orm/session.py", line 1981, in _connection_for_bind
    return trans._connection_for_bind(engine, execution_options)
  File "<string>", line 2, in _connection_for_bind
  File "/home/dcy/anaconda3/envs/EDRE3D/lib/python3.8/site-packages/sqlalchemy/orm/state_changes.py", line 137, in _go
    ret_value = fn(self, *arg, **kw)
  File "/home/dcy/anaconda3/envs/EDRE3D/lib/python3.8/site-packages/sqlalchemy/orm/session.py", line 1108, in _connection_for_bind
    conn = bind.connect()
  File "/home/dcy/anaconda3/envs/EDRE3D/lib/python3.8/site-packages/sqlalchemy/engine/base.py", line 3251, in connect
    return self._connection_cls(self)
  File "/home/dcy/anaconda3/envs/EDRE3D/lib/python3.8/site-packages/sqlalchemy/engine/base.py", line 147, in __init__
    Connection._handle_dbapi_exception_noconnection(
  File "/home/dcy/anaconda3/envs/EDRE3D/lib/python3.8/site-packages/sqlalchemy/engine/base.py", line 2413, in _handle_dbapi_exception_noconnection
    raise sqlalchemy_exception.with_traceback(exc_info[2]) from e
  File "/home/dcy/anaconda3/envs/EDRE3D/lib/python3.8/site-packages/sqlalchemy/engine/base.py", line 145, in __init__
    self._dbapi_connection = engine.raw_connection()
  File "/home/dcy/anaconda3/envs/EDRE3D/lib/python3.8/site-packages/sqlalchemy/engine/base.py", line 3275, in raw_connection
    return self.pool.connect()
  File "/home/dcy/anaconda3/envs/EDRE3D/lib/python3.8/site-packages/sqlalchemy/pool/base.py", line 455, in connect
    return _ConnectionFairy._checkout(self)
  File "/home/dcy/anaconda3/envs/EDRE3D/lib/python3.8/site-packages/sqlalchemy/pool/base.py", line 1271, in _checkout
    fairy = _ConnectionRecord.checkout(pool)
  File "/home/dcy/anaconda3/envs/EDRE3D/lib/python3.8/site-packages/sqlalchemy/pool/base.py", line 725, in checkout
    rec._checkin_failed(err, _fairy_was_created=False)
  File "/home/dcy/anaconda3/envs/EDRE3D/lib/python3.8/site-packages/sqlalchemy/util/langhelpers.py", line 147, in __exit__
    raise exc_value.with_traceback(exc_tb)
  File "/home/dcy/anaconda3/envs/EDRE3D/lib/python3.8/site-packages/sqlalchemy/pool/base.py", line 722, in checkout
    dbapi_connection = rec.get_connection()
  File "/home/dcy/anaconda3/envs/EDRE3D/lib/python3.8/site-packages/sqlalchemy/pool/base.py", line 842, in get_connection
    self.__connect()
  File "/home/dcy/anaconda3/envs/EDRE3D/lib/python3.8/site-packages/sqlalchemy/pool/base.py", line 906, in __connect
    pool.logger.debug("Error on connect(): %s", e)
  File "/home/dcy/anaconda3/envs/EDRE3D/lib/python3.8/site-packages/sqlalchemy/util/langhelpers.py", line 147, in __exit__
    raise exc_value.with_traceback(exc_tb)
  File "/home/dcy/anaconda3/envs/EDRE3D/lib/python3.8/site-packages/sqlalchemy/pool/base.py", line 901, in __connect
    self.dbapi_connection = connection = pool._invoke_creator(self)
  File "/home/dcy/anaconda3/envs/EDRE3D/lib/python3.8/site-packages/sqlalchemy/engine/create.py", line 636, in connect
    return dialect.connect(*cargs, **cparams)
  File "/home/dcy/anaconda3/envs/EDRE3D/lib/python3.8/site-packages/sqlalchemy/engine/default.py", line 580, in connect
    return self.loaded_dbapi.connect(*cargs, **cparams)
  File "/home/dcy/anaconda3/envs/EDRE3D/lib/python3.8/site-packages/pymysql/connections.py", line 352, in __init__
    self.connect()
  File "/home/dcy/anaconda3/envs/EDRE3D/lib/python3.8/site-packages/pymysql/connections.py", line 668, in connect
    raise exc
sqlalchemy.exc.OperationalError: (pymysql.err.OperationalError) (2003, "Can't connect to MySQL server on '10.162.220.155' (timed out)")
(Background on this error at: https://sqlalche.me/e/20/e3q8)
10.162.135.151 - - [2023-05-03 21:42:45] "GET /api/getAllProjects HTTP/1.1" 500 467 10.012192
[2023-05-03 21:42:55,205] ERROR in app: Exception on /api/getAllProjects [GET]
Traceback (most recent call last):
  File "/home/dcy/anaconda3/envs/EDRE3D/lib/python3.8/site-packages/pymysql/connections.py", line 616, in connect
    sock = socket.create_connection(
  File "/home/dcy/anaconda3/envs/EDRE3D/lib/python3.8/socket.py", line 808, in create_connection
    raise err
  File "/home/dcy/anaconda3/envs/EDRE3D/lib/python3.8/socket.py", line 796, in create_connection
    sock.connect(sa)
socket.timeout: timed out

During handling of the above exception, another exception occurred:

Traceback (most recent call last):
  File "/home/dcy/anaconda3/envs/EDRE3D/lib/python3.8/site-packages/sqlalchemy/engine/base.py", line 145, in __init__
    self._dbapi_connection = engine.raw_connection()
  File "/home/dcy/anaconda3/envs/EDRE3D/lib/python3.8/site-packages/sqlalchemy/engine/base.py", line 3275, in raw_connection
    return self.pool.connect()
  File "/home/dcy/anaconda3/envs/EDRE3D/lib/python3.8/site-packages/sqlalchemy/pool/base.py", line 455, in connect
    return _ConnectionFairy._checkout(self)
  File "/home/dcy/anaconda3/envs/EDRE3D/lib/python3.8/site-packages/sqlalchemy/pool/base.py", line 1271, in _checkout
    fairy = _ConnectionRecord.checkout(pool)
  File "/home/dcy/anaconda3/envs/EDRE3D/lib/python3.8/site-packages/sqlalchemy/pool/base.py", line 725, in checkout
    rec._checkin_failed(err, _fairy_was_created=False)
  File "/home/dcy/anaconda3/envs/EDRE3D/lib/python3.8/site-packages/sqlalchemy/util/langhelpers.py", line 147, in __exit__
    raise exc_value.with_traceback(exc_tb)
  File "/home/dcy/anaconda3/envs/EDRE3D/lib/python3.8/site-packages/sqlalchemy/pool/base.py", line 722, in checkout
    dbapi_connection = rec.get_connection()
  File "/home/dcy/anaconda3/envs/EDRE3D/lib/python3.8/site-packages/sqlalchemy/pool/base.py", line 842, in get_connection
    self.__connect()
  File "/home/dcy/anaconda3/envs/EDRE3D/lib/python3.8/site-packages/sqlalchemy/pool/base.py", line 906, in __connect
    pool.logger.debug("Error on connect(): %s", e)
  File "/home/dcy/anaconda3/envs/EDRE3D/lib/python3.8/site-packages/sqlalchemy/util/langhelpers.py", line 147, in __exit__
    raise exc_value.with_traceback(exc_tb)
  File "/home/dcy/anaconda3/envs/EDRE3D/lib/python3.8/site-packages/sqlalchemy/pool/base.py", line 901, in __connect
    self.dbapi_connection = connection = pool._invoke_creator(self)
  File "/home/dcy/anaconda3/envs/EDRE3D/lib/python3.8/site-packages/sqlalchemy/engine/create.py", line 636, in connect
    return dialect.connect(*cargs, **cparams)
  File "/home/dcy/anaconda3/envs/EDRE3D/lib/python3.8/site-packages/sqlalchemy/engine/default.py", line 580, in connect
    return self.loaded_dbapi.connect(*cargs, **cparams)
  File "/home/dcy/anaconda3/envs/EDRE3D/lib/python3.8/site-packages/pymysql/connections.py", line 352, in __init__
    self.connect()
  File "/home/dcy/anaconda3/envs/EDRE3D/lib/python3.8/site-packages/pymysql/connections.py", line 668, in connect
    raise exc
pymysql.err.OperationalError: (2003, "Can't connect to MySQL server on '10.162.220.155' (timed out)")

The above exception was the direct cause of the following exception:

Traceback (most recent call last):
  File "/home/dcy/anaconda3/envs/EDRE3D/lib/python3.8/site-packages/flask/app.py", line 2528, in wsgi_app
    response = self.full_dispatch_request()
  File "/home/dcy/anaconda3/envs/EDRE3D/lib/python3.8/site-packages/flask/app.py", line 1825, in full_dispatch_request
    rv = self.handle_user_exception(e)
  File "/home/dcy/anaconda3/envs/EDRE3D/lib/python3.8/site-packages/flask_cors/extension.py", line 165, in wrapped_function
    return cors_after_request(app.make_response(f(*args, **kwargs)))
  File "/home/dcy/anaconda3/envs/EDRE3D/lib/python3.8/site-packages/flask/app.py", line 1823, in full_dispatch_request
    rv = self.dispatch_request()
  File "/home/dcy/anaconda3/envs/EDRE3D/lib/python3.8/site-packages/flask/app.py", line 1799, in dispatch_request
    return self.ensure_sync(self.view_functions[rule.endpoint])(**view_args)
  File "/home/dcy/code/EDREserver/app/api/views.py", line 68, in getAllProjects
    projectList = ProjectList.query.all()
  File "/home/dcy/anaconda3/envs/EDRE3D/lib/python3.8/site-packages/sqlalchemy/orm/query.py", line 2697, in all
    return self._iter().all()  # type: ignore
  File "/home/dcy/anaconda3/envs/EDRE3D/lib/python3.8/site-packages/sqlalchemy/orm/query.py", line 2855, in _iter
    result: Union[ScalarResult[_T], Result[_T]] = self.session.execute(
  File "/home/dcy/anaconda3/envs/EDRE3D/lib/python3.8/site-packages/sqlalchemy/orm/session.py", line 2229, in execute
    return self._execute_internal(
  File "/home/dcy/anaconda3/envs/EDRE3D/lib/python3.8/site-packages/sqlalchemy/orm/session.py", line 2114, in _execute_internal
    conn = self._connection_for_bind(bind)
  File "/home/dcy/anaconda3/envs/EDRE3D/lib/python3.8/site-packages/sqlalchemy/orm/session.py", line 1981, in _connection_for_bind
    return trans._connection_for_bind(engine, execution_options)
  File "<string>", line 2, in _connection_for_bind
  File "/home/dcy/anaconda3/envs/EDRE3D/lib/python3.8/site-packages/sqlalchemy/orm/state_changes.py", line 137, in _go
    ret_value = fn(self, *arg, **kw)
  File "/home/dcy/anaconda3/envs/EDRE3D/lib/python3.8/site-packages/sqlalchemy/orm/session.py", line 1108, in _connection_for_bind
    conn = bind.connect()
  File "/home/dcy/anaconda3/envs/EDRE3D/lib/python3.8/site-packages/sqlalchemy/engine/base.py", line 3251, in connect
    return self._connection_cls(self)
  File "/home/dcy/anaconda3/envs/EDRE3D/lib/python3.8/site-packages/sqlalchemy/engine/base.py", line 147, in __init__
    Connection._handle_dbapi_exception_noconnection(
  File "/home/dcy/anaconda3/envs/EDRE3D/lib/python3.8/site-packages/sqlalchemy/engine/base.py", line 2413, in _handle_dbapi_exception_noconnection
    raise sqlalchemy_exception.with_traceback(exc_info[2]) from e
  File "/home/dcy/anaconda3/envs/EDRE3D/lib/python3.8/site-packages/sqlalchemy/engine/base.py", line 145, in __init__
    self._dbapi_connection = engine.raw_connection()
  File "/home/dcy/anaconda3/envs/EDRE3D/lib/python3.8/site-packages/sqlalchemy/engine/base.py", line 3275, in raw_connection
    return self.pool.connect()
  File "/home/dcy/anaconda3/envs/EDRE3D/lib/python3.8/site-packages/sqlalchemy/pool/base.py", line 455, in connect
    return _ConnectionFairy._checkout(self)
  File "/home/dcy/anaconda3/envs/EDRE3D/lib/python3.8/site-packages/sqlalchemy/pool/base.py", line 1271, in _checkout
    fairy = _ConnectionRecord.checkout(pool)
  File "/home/dcy/anaconda3/envs/EDRE3D/lib/python3.8/site-packages/sqlalchemy/pool/base.py", line 725, in checkout
    rec._checkin_failed(err, _fairy_was_created=False)
  File "/home/dcy/anaconda3/envs/EDRE3D/lib/python3.8/site-packages/sqlalchemy/util/langhelpers.py", line 147, in __exit__
    raise exc_value.with_traceback(exc_tb)
  File "/home/dcy/anaconda3/envs/EDRE3D/lib/python3.8/site-packages/sqlalchemy/pool/base.py", line 722, in checkout
    dbapi_connection = rec.get_connection()
  File "/home/dcy/anaconda3/envs/EDRE3D/lib/python3.8/site-packages/sqlalchemy/pool/base.py", line 842, in get_connection
    self.__connect()
  File "/home/dcy/anaconda3/envs/EDRE3D/lib/python3.8/site-packages/sqlalchemy/pool/base.py", line 906, in __connect
    pool.logger.debug("Error on connect(): %s", e)
  File "/home/dcy/anaconda3/envs/EDRE3D/lib/python3.8/site-packages/sqlalchemy/util/langhelpers.py", line 147, in __exit__
    raise exc_value.with_traceback(exc_tb)
  File "/home/dcy/anaconda3/envs/EDRE3D/lib/python3.8/site-packages/sqlalchemy/pool/base.py", line 901, in __connect
    self.dbapi_connection = connection = pool._invoke_creator(self)
  File "/home/dcy/anaconda3/envs/EDRE3D/lib/python3.8/site-packages/sqlalchemy/engine/create.py", line 636, in connect
    return dialect.connect(*cargs, **cparams)
  File "/home/dcy/anaconda3/envs/EDRE3D/lib/python3.8/site-packages/sqlalchemy/engine/default.py", line 580, in connect
    return self.loaded_dbapi.connect(*cargs, **cparams)
  File "/home/dcy/anaconda3/envs/EDRE3D/lib/python3.8/site-packages/pymysql/connections.py", line 352, in __init__
    self.connect()
  File "/home/dcy/anaconda3/envs/EDRE3D/lib/python3.8/site-packages/pymysql/connections.py", line 668, in connect
    raise exc
sqlalchemy.exc.OperationalError: (pymysql.err.OperationalError) (2003, "Can't connect to MySQL server on '10.162.220.155' (timed out)")
(Background on this error at: https://sqlalche.me/e/20/e3q8)
10.162.135.151 - - [2023-05-03 21:42:55] "GET /api/getAllProjects HTTP/1.1" 500 467 10.010927
[2023-05-03 21:43:05,210] ERROR in app: Exception on /api/getAllProjects [GET]
Traceback (most recent call last):
  File "/home/dcy/anaconda3/envs/EDRE3D/lib/python3.8/site-packages/pymysql/connections.py", line 616, in connect
    sock = socket.create_connection(
  File "/home/dcy/anaconda3/envs/EDRE3D/lib/python3.8/socket.py", line 808, in create_connection
    raise err
  File "/home/dcy/anaconda3/envs/EDRE3D/lib/python3.8/socket.py", line 796, in create_connection
    sock.connect(sa)
socket.timeout: timed out

During handling of the above exception, another exception occurred:

Traceback (most recent call last):
  File "/home/dcy/anaconda3/envs/EDRE3D/lib/python3.8/site-packages/sqlalchemy/engine/base.py", line 145, in __init__
    self._dbapi_connection = engine.raw_connection()
  File "/home/dcy/anaconda3/envs/EDRE3D/lib/python3.8/site-packages/sqlalchemy/engine/base.py", line 3275, in raw_connection
    return self.pool.connect()
  File "/home/dcy/anaconda3/envs/EDRE3D/lib/python3.8/site-packages/sqlalchemy/pool/base.py", line 455, in connect
    return _ConnectionFairy._checkout(self)
  File "/home/dcy/anaconda3/envs/EDRE3D/lib/python3.8/site-packages/sqlalchemy/pool/base.py", line 1271, in _checkout
    fairy = _ConnectionRecord.checkout(pool)
  File "/home/dcy/anaconda3/envs/EDRE3D/lib/python3.8/site-packages/sqlalchemy/pool/base.py", line 725, in checkout
    rec._checkin_failed(err, _fairy_was_created=False)
  File "/home/dcy/anaconda3/envs/EDRE3D/lib/python3.8/site-packages/sqlalchemy/util/langhelpers.py", line 147, in __exit__
    raise exc_value.with_traceback(exc_tb)
  File "/home/dcy/anaconda3/envs/EDRE3D/lib/python3.8/site-packages/sqlalchemy/pool/base.py", line 722, in checkout
    dbapi_connection = rec.get_connection()
  File "/home/dcy/anaconda3/envs/EDRE3D/lib/python3.8/site-packages/sqlalchemy/pool/base.py", line 842, in get_connection
    self.__connect()
  File "/home/dcy/anaconda3/envs/EDRE3D/lib/python3.8/site-packages/sqlalchemy/pool/base.py", line 906, in __connect
    pool.logger.debug("Error on connect(): %s", e)
  File "/home/dcy/anaconda3/envs/EDRE3D/lib/python3.8/site-packages/sqlalchemy/util/langhelpers.py", line 147, in __exit__
    raise exc_value.with_traceback(exc_tb)
  File "/home/dcy/anaconda3/envs/EDRE3D/lib/python3.8/site-packages/sqlalchemy/pool/base.py", line 901, in __connect
    self.dbapi_connection = connection = pool._invoke_creator(self)
  File "/home/dcy/anaconda3/envs/EDRE3D/lib/python3.8/site-packages/sqlalchemy/engine/create.py", line 636, in connect
    return dialect.connect(*cargs, **cparams)
  File "/home/dcy/anaconda3/envs/EDRE3D/lib/python3.8/site-packages/sqlalchemy/engine/default.py", line 580, in connect
    return self.loaded_dbapi.connect(*cargs, **cparams)
  File "/home/dcy/anaconda3/envs/EDRE3D/lib/python3.8/site-packages/pymysql/connections.py", line 352, in __init__
    self.connect()
  File "/home/dcy/anaconda3/envs/EDRE3D/lib/python3.8/site-packages/pymysql/connections.py", line 668, in connect
    raise exc
pymysql.err.OperationalError: (2003, "Can't connect to MySQL server on '10.162.220.155' (timed out)")

The above exception was the direct cause of the following exception:

Traceback (most recent call last):
  File "/home/dcy/anaconda3/envs/EDRE3D/lib/python3.8/site-packages/flask/app.py", line 2528, in wsgi_app
    response = self.full_dispatch_request()
  File "/home/dcy/anaconda3/envs/EDRE3D/lib/python3.8/site-packages/flask/app.py", line 1825, in full_dispatch_request
    rv = self.handle_user_exception(e)
  File "/home/dcy/anaconda3/envs/EDRE3D/lib/python3.8/site-packages/flask_cors/extension.py", line 165, in wrapped_function
    return cors_after_request(app.make_response(f(*args, **kwargs)))
  File "/home/dcy/anaconda3/envs/EDRE3D/lib/python3.8/site-packages/flask/app.py", line 1823, in full_dispatch_request
    rv = self.dispatch_request()
  File "/home/dcy/anaconda3/envs/EDRE3D/lib/python3.8/site-packages/flask/app.py", line 1799, in dispatch_request
    return self.ensure_sync(self.view_functions[rule.endpoint])(**view_args)
  File "/home/dcy/code/EDREserver/app/api/views.py", line 68, in getAllProjects
    projectList = ProjectList.query.all()
  File "/home/dcy/anaconda3/envs/EDRE3D/lib/python3.8/site-packages/sqlalchemy/orm/query.py", line 2697, in all
    return self._iter().all()  # type: ignore
  File "/home/dcy/anaconda3/envs/EDRE3D/lib/python3.8/site-packages/sqlalchemy/orm/query.py", line 2855, in _iter
    result: Union[ScalarResult[_T], Result[_T]] = self.session.execute(
  File "/home/dcy/anaconda3/envs/EDRE3D/lib/python3.8/site-packages/sqlalchemy/orm/session.py", line 2229, in execute
    return self._execute_internal(
  File "/home/dcy/anaconda3/envs/EDRE3D/lib/python3.8/site-packages/sqlalchemy/orm/session.py", line 2114, in _execute_internal
    conn = self._connection_for_bind(bind)
  File "/home/dcy/anaconda3/envs/EDRE3D/lib/python3.8/site-packages/sqlalchemy/orm/session.py", line 1981, in _connection_for_bind
    return trans._connection_for_bind(engine, execution_options)
  File "<string>", line 2, in _connection_for_bind
  File "/home/dcy/anaconda3/envs/EDRE3D/lib/python3.8/site-packages/sqlalchemy/orm/state_changes.py", line 137, in _go
    ret_value = fn(self, *arg, **kw)
  File "/home/dcy/anaconda3/envs/EDRE3D/lib/python3.8/site-packages/sqlalchemy/orm/session.py", line 1108, in _connection_for_bind
    conn = bind.connect()
  File "/home/dcy/anaconda3/envs/EDRE3D/lib/python3.8/site-packages/sqlalchemy/engine/base.py", line 3251, in connect
    return self._connection_cls(self)
  File "/home/dcy/anaconda3/envs/EDRE3D/lib/python3.8/site-packages/sqlalchemy/engine/base.py", line 147, in __init__
    Connection._handle_dbapi_exception_noconnection(
  File "/home/dcy/anaconda3/envs/EDRE3D/lib/python3.8/site-packages/sqlalchemy/engine/base.py", line 2413, in _handle_dbapi_exception_noconnection
    raise sqlalchemy_exception.with_traceback(exc_info[2]) from e
  File "/home/dcy/anaconda3/envs/EDRE3D/lib/python3.8/site-packages/sqlalchemy/engine/base.py", line 145, in __init__
    self._dbapi_connection = engine.raw_connection()
  File "/home/dcy/anaconda3/envs/EDRE3D/lib/python3.8/site-packages/sqlalchemy/engine/base.py", line 3275, in raw_connection
    return self.pool.connect()
  File "/home/dcy/anaconda3/envs/EDRE3D/lib/python3.8/site-packages/sqlalchemy/pool/base.py", line 455, in connect
    return _ConnectionFairy._checkout(self)
  File "/home/dcy/anaconda3/envs/EDRE3D/lib/python3.8/site-packages/sqlalchemy/pool/base.py", line 1271, in _checkout
    fairy = _ConnectionRecord.checkout(pool)
  File "/home/dcy/anaconda3/envs/EDRE3D/lib/python3.8/site-packages/sqlalchemy/pool/base.py", line 725, in checkout
    rec._checkin_failed(err, _fairy_was_created=False)
  File "/home/dcy/anaconda3/envs/EDRE3D/lib/python3.8/site-packages/sqlalchemy/util/langhelpers.py", line 147, in __exit__
    raise exc_value.with_traceback(exc_tb)
  File "/home/dcy/anaconda3/envs/EDRE3D/lib/python3.8/site-packages/sqlalchemy/pool/base.py", line 722, in checkout
    dbapi_connection = rec.get_connection()
  File "/home/dcy/anaconda3/envs/EDRE3D/lib/python3.8/site-packages/sqlalchemy/pool/base.py", line 842, in get_connection
    self.__connect()
  File "/home/dcy/anaconda3/envs/EDRE3D/lib/python3.8/site-packages/sqlalchemy/pool/base.py", line 906, in __connect
    pool.logger.debug("Error on connect(): %s", e)
  File "/home/dcy/anaconda3/envs/EDRE3D/lib/python3.8/site-packages/sqlalchemy/util/langhelpers.py", line 147, in __exit__
    raise exc_value.with_traceback(exc_tb)
  File "/home/dcy/anaconda3/envs/EDRE3D/lib/python3.8/site-packages/sqlalchemy/pool/base.py", line 901, in __connect
    self.dbapi_connection = connection = pool._invoke_creator(self)
  File "/home/dcy/anaconda3/envs/EDRE3D/lib/python3.8/site-packages/sqlalchemy/engine/create.py", line 636, in connect
    return dialect.connect(*cargs, **cparams)
  File "/home/dcy/anaconda3/envs/EDRE3D/lib/python3.8/site-packages/sqlalchemy/engine/default.py", line 580, in connect
    return self.loaded_dbapi.connect(*cargs, **cparams)
  File "/home/dcy/anaconda3/envs/EDRE3D/lib/python3.8/site-packages/pymysql/connections.py", line 352, in __init__
    self.connect()
  File "/home/dcy/anaconda3/envs/EDRE3D/lib/python3.8/site-packages/pymysql/connections.py", line 668, in connect
    raise exc
sqlalchemy.exc.OperationalError: (pymysql.err.OperationalError) (2003, "Can't connect to MySQL server on '10.162.220.155' (timed out)")
(Background on this error at: https://sqlalche.me/e/20/e3q8)
10.162.135.151 - - [2023-05-03 21:43:05] "GET /api/getAllProjects HTTP/1.1" 500 467 10.004872
[2023-05-03 21:43:15,221] ERROR in app: Exception on /api/getAllProjects [GET]
Traceback (most recent call last):
  File "/home/dcy/anaconda3/envs/EDRE3D/lib/python3.8/site-packages/pymysql/connections.py", line 616, in connect
    sock = socket.create_connection(
  File "/home/dcy/anaconda3/envs/EDRE3D/lib/python3.8/socket.py", line 808, in create_connection
    raise err
  File "/home/dcy/anaconda3/envs/EDRE3D/lib/python3.8/socket.py", line 796, in create_connection
    sock.connect(sa)
socket.timeout: timed out

During handling of the above exception, another exception occurred:

Traceback (most recent call last):
  File "/home/dcy/anaconda3/envs/EDRE3D/lib/python3.8/site-packages/sqlalchemy/engine/base.py", line 145, in __init__
    self._dbapi_connection = engine.raw_connection()
  File "/home/dcy/anaconda3/envs/EDRE3D/lib/python3.8/site-packages/sqlalchemy/engine/base.py", line 3275, in raw_connection
    return self.pool.connect()
  File "/home/dcy/anaconda3/envs/EDRE3D/lib/python3.8/site-packages/sqlalchemy/pool/base.py", line 455, in connect
    return _ConnectionFairy._checkout(self)
  File "/home/dcy/anaconda3/envs/EDRE3D/lib/python3.8/site-packages/sqlalchemy/pool/base.py", line 1271, in _checkout
    fairy = _ConnectionRecord.checkout(pool)
  File "/home/dcy/anaconda3/envs/EDRE3D/lib/python3.8/site-packages/sqlalchemy/pool/base.py", line 725, in checkout
    rec._checkin_failed(err, _fairy_was_created=False)
  File "/home/dcy/anaconda3/envs/EDRE3D/lib/python3.8/site-packages/sqlalchemy/util/langhelpers.py", line 147, in __exit__
    raise exc_value.with_traceback(exc_tb)
  File "/home/dcy/anaconda3/envs/EDRE3D/lib/python3.8/site-packages/sqlalchemy/pool/base.py", line 722, in checkout
    dbapi_connection = rec.get_connection()
  File "/home/dcy/anaconda3/envs/EDRE3D/lib/python3.8/site-packages/sqlalchemy/pool/base.py", line 842, in get_connection
    self.__connect()
  File "/home/dcy/anaconda3/envs/EDRE3D/lib/python3.8/site-packages/sqlalchemy/pool/base.py", line 906, in __connect
    pool.logger.debug("Error on connect(): %s", e)
  File "/home/dcy/anaconda3/envs/EDRE3D/lib/python3.8/site-packages/sqlalchemy/util/langhelpers.py", line 147, in __exit__
    raise exc_value.with_traceback(exc_tb)
  File "/home/dcy/anaconda3/envs/EDRE3D/lib/python3.8/site-packages/sqlalchemy/pool/base.py", line 901, in __connect
    self.dbapi_connection = connection = pool._invoke_creator(self)
  File "/home/dcy/anaconda3/envs/EDRE3D/lib/python3.8/site-packages/sqlalchemy/engine/create.py", line 636, in connect
    return dialect.connect(*cargs, **cparams)
  File "/home/dcy/anaconda3/envs/EDRE3D/lib/python3.8/site-packages/sqlalchemy/engine/default.py", line 580, in connect
    return self.loaded_dbapi.connect(*cargs, **cparams)
  File "/home/dcy/anaconda3/envs/EDRE3D/lib/python3.8/site-packages/pymysql/connections.py", line 352, in __init__
    self.connect()
  File "/home/dcy/anaconda3/envs/EDRE3D/lib/python3.8/site-packages/pymysql/connections.py", line 668, in connect
    raise exc
pymysql.err.OperationalError: (2003, "Can't connect to MySQL server on '10.162.220.155' (timed out)")

The above exception was the direct cause of the following exception:

Traceback (most recent call last):
  File "/home/dcy/anaconda3/envs/EDRE3D/lib/python3.8/site-packages/flask/app.py", line 2528, in wsgi_app
    response = self.full_dispatch_request()
  File "/home/dcy/anaconda3/envs/EDRE3D/lib/python3.8/site-packages/flask/app.py", line 1825, in full_dispatch_request
    rv = self.handle_user_exception(e)
  File "/home/dcy/anaconda3/envs/EDRE3D/lib/python3.8/site-packages/flask_cors/extension.py", line 165, in wrapped_function
    return cors_after_request(app.make_response(f(*args, **kwargs)))
  File "/home/dcy/anaconda3/envs/EDRE3D/lib/python3.8/site-packages/flask/app.py", line 1823, in full_dispatch_request
    rv = self.dispatch_request()
  File "/home/dcy/anaconda3/envs/EDRE3D/lib/python3.8/site-packages/flask/app.py", line 1799, in dispatch_request
    return self.ensure_sync(self.view_functions[rule.endpoint])(**view_args)
  File "/home/dcy/code/EDREserver/app/api/views.py", line 68, in getAllProjects
    projectList = ProjectList.query.all()
  File "/home/dcy/anaconda3/envs/EDRE3D/lib/python3.8/site-packages/sqlalchemy/orm/query.py", line 2697, in all
    return self._iter().all()  # type: ignore
  File "/home/dcy/anaconda3/envs/EDRE3D/lib/python3.8/site-packages/sqlalchemy/orm/query.py", line 2855, in _iter
    result: Union[ScalarResult[_T], Result[_T]] = self.session.execute(
  File "/home/dcy/anaconda3/envs/EDRE3D/lib/python3.8/site-packages/sqlalchemy/orm/session.py", line 2229, in execute
    return self._execute_internal(
  File "/home/dcy/anaconda3/envs/EDRE3D/lib/python3.8/site-packages/sqlalchemy/orm/session.py", line 2114, in _execute_internal
    conn = self._connection_for_bind(bind)
  File "/home/dcy/anaconda3/envs/EDRE3D/lib/python3.8/site-packages/sqlalchemy/orm/session.py", line 1981, in _connection_for_bind
    return trans._connection_for_bind(engine, execution_options)
  File "<string>", line 2, in _connection_for_bind
  File "/home/dcy/anaconda3/envs/EDRE3D/lib/python3.8/site-packages/sqlalchemy/orm/state_changes.py", line 137, in _go
    ret_value = fn(self, *arg, **kw)
  File "/home/dcy/anaconda3/envs/EDRE3D/lib/python3.8/site-packages/sqlalchemy/orm/session.py", line 1108, in _connection_for_bind
    conn = bind.connect()
  File "/home/dcy/anaconda3/envs/EDRE3D/lib/python3.8/site-packages/sqlalchemy/engine/base.py", line 3251, in connect
    return self._connection_cls(self)
  File "/home/dcy/anaconda3/envs/EDRE3D/lib/python3.8/site-packages/sqlalchemy/engine/base.py", line 147, in __init__
    Connection._handle_dbapi_exception_noconnection(
  File "/home/dcy/anaconda3/envs/EDRE3D/lib/python3.8/site-packages/sqlalchemy/engine/base.py", line 2413, in _handle_dbapi_exception_noconnection
    raise sqlalchemy_exception.with_traceback(exc_info[2]) from e
  File "/home/dcy/anaconda3/envs/EDRE3D/lib/python3.8/site-packages/sqlalchemy/engine/base.py", line 145, in __init__
    self._dbapi_connection = engine.raw_connection()
  File "/home/dcy/anaconda3/envs/EDRE3D/lib/python3.8/site-packages/sqlalchemy/engine/base.py", line 3275, in raw_connection
    return self.pool.connect()
  File "/home/dcy/anaconda3/envs/EDRE3D/lib/python3.8/site-packages/sqlalchemy/pool/base.py", line 455, in connect
    return _ConnectionFairy._checkout(self)
  File "/home/dcy/anaconda3/envs/EDRE3D/lib/python3.8/site-packages/sqlalchemy/pool/base.py", line 1271, in _checkout
    fairy = _ConnectionRecord.checkout(pool)
  File "/home/dcy/anaconda3/envs/EDRE3D/lib/python3.8/site-packages/sqlalchemy/pool/base.py", line 725, in checkout
    rec._checkin_failed(err, _fairy_was_created=False)
  File "/home/dcy/anaconda3/envs/EDRE3D/lib/python3.8/site-packages/sqlalchemy/util/langhelpers.py", line 147, in __exit__
    raise exc_value.with_traceback(exc_tb)
  File "/home/dcy/anaconda3/envs/EDRE3D/lib/python3.8/site-packages/sqlalchemy/pool/base.py", line 722, in checkout
    dbapi_connection = rec.get_connection()
  File "/home/dcy/anaconda3/envs/EDRE3D/lib/python3.8/site-packages/sqlalchemy/pool/base.py", line 842, in get_connection
    self.__connect()
  File "/home/dcy/anaconda3/envs/EDRE3D/lib/python3.8/site-packages/sqlalchemy/pool/base.py", line 906, in __connect
    pool.logger.debug("Error on connect(): %s", e)
  File "/home/dcy/anaconda3/envs/EDRE3D/lib/python3.8/site-packages/sqlalchemy/util/langhelpers.py", line 147, in __exit__
    raise exc_value.with_traceback(exc_tb)
  File "/home/dcy/anaconda3/envs/EDRE3D/lib/python3.8/site-packages/sqlalchemy/pool/base.py", line 901, in __connect
    self.dbapi_connection = connection = pool._invoke_creator(self)
  File "/home/dcy/anaconda3/envs/EDRE3D/lib/python3.8/site-packages/sqlalchemy/engine/create.py", line 636, in connect
    return dialect.connect(*cargs, **cparams)
  File "/home/dcy/anaconda3/envs/EDRE3D/lib/python3.8/site-packages/sqlalchemy/engine/default.py", line 580, in connect
    return self.loaded_dbapi.connect(*cargs, **cparams)
  File "/home/dcy/anaconda3/envs/EDRE3D/lib/python3.8/site-packages/pymysql/connections.py", line 352, in __init__
    self.connect()
  File "/home/dcy/anaconda3/envs/EDRE3D/lib/python3.8/site-packages/pymysql/connections.py", line 668, in connect
    raise exc
sqlalchemy.exc.OperationalError: (pymysql.err.OperationalError) (2003, "Can't connect to MySQL server on '10.162.220.155' (timed out)")
(Background on this error at: https://sqlalche.me/e/20/e3q8)
10.162.135.151 - - [2023-05-03 21:43:15] "GET /api/getAllProjects HTTP/1.1" 500 467 10.010663
[2023-05-03 21:43:25,230] ERROR in app: Exception on /api/getAllProjects [GET]
Traceback (most recent call last):
  File "/home/dcy/anaconda3/envs/EDRE3D/lib/python3.8/site-packages/pymysql/connections.py", line 616, in connect
    sock = socket.create_connection(
  File "/home/dcy/anaconda3/envs/EDRE3D/lib/python3.8/socket.py", line 808, in create_connection
    raise err
  File "/home/dcy/anaconda3/envs/EDRE3D/lib/python3.8/socket.py", line 796, in create_connection
    sock.connect(sa)
socket.timeout: timed out

During handling of the above exception, another exception occurred:

Traceback (most recent call last):
  File "/home/dcy/anaconda3/envs/EDRE3D/lib/python3.8/site-packages/sqlalchemy/engine/base.py", line 145, in __init__
    self._dbapi_connection = engine.raw_connection()
  File "/home/dcy/anaconda3/envs/EDRE3D/lib/python3.8/site-packages/sqlalchemy/engine/base.py", line 3275, in raw_connection
    return self.pool.connect()
  File "/home/dcy/anaconda3/envs/EDRE3D/lib/python3.8/site-packages/sqlalchemy/pool/base.py", line 455, in connect
    return _ConnectionFairy._checkout(self)
  File "/home/dcy/anaconda3/envs/EDRE3D/lib/python3.8/site-packages/sqlalchemy/pool/base.py", line 1271, in _checkout
    fairy = _ConnectionRecord.checkout(pool)
  File "/home/dcy/anaconda3/envs/EDRE3D/lib/python3.8/site-packages/sqlalchemy/pool/base.py", line 725, in checkout
    rec._checkin_failed(err, _fairy_was_created=False)
  File "/home/dcy/anaconda3/envs/EDRE3D/lib/python3.8/site-packages/sqlalchemy/util/langhelpers.py", line 147, in __exit__
    raise exc_value.with_traceback(exc_tb)
  File "/home/dcy/anaconda3/envs/EDRE3D/lib/python3.8/site-packages/sqlalchemy/pool/base.py", line 722, in checkout
    dbapi_connection = rec.get_connection()
  File "/home/dcy/anaconda3/envs/EDRE3D/lib/python3.8/site-packages/sqlalchemy/pool/base.py", line 842, in get_connection
    self.__connect()
  File "/home/dcy/anaconda3/envs/EDRE3D/lib/python3.8/site-packages/sqlalchemy/pool/base.py", line 906, in __connect
    pool.logger.debug("Error on connect(): %s", e)
  File "/home/dcy/anaconda3/envs/EDRE3D/lib/python3.8/site-packages/sqlalchemy/util/langhelpers.py", line 147, in __exit__
    raise exc_value.with_traceback(exc_tb)
  File "/home/dcy/anaconda3/envs/EDRE3D/lib/python3.8/site-packages/sqlalchemy/pool/base.py", line 901, in __connect
    self.dbapi_connection = connection = pool._invoke_creator(self)
  File "/home/dcy/anaconda3/envs/EDRE3D/lib/python3.8/site-packages/sqlalchemy/engine/create.py", line 636, in connect
    return dialect.connect(*cargs, **cparams)
  File "/home/dcy/anaconda3/envs/EDRE3D/lib/python3.8/site-packages/sqlalchemy/engine/default.py", line 580, in connect
    return self.loaded_dbapi.connect(*cargs, **cparams)
  File "/home/dcy/anaconda3/envs/EDRE3D/lib/python3.8/site-packages/pymysql/connections.py", line 352, in __init__
    self.connect()
  File "/home/dcy/anaconda3/envs/EDRE3D/lib/python3.8/site-packages/pymysql/connections.py", line 668, in connect
    raise exc
pymysql.err.OperationalError: (2003, "Can't connect to MySQL server on '10.162.220.155' (timed out)")

The above exception was the direct cause of the following exception:

Traceback (most recent call last):
  File "/home/dcy/anaconda3/envs/EDRE3D/lib/python3.8/site-packages/flask/app.py", line 2528, in wsgi_app
    response = self.full_dispatch_request()
  File "/home/dcy/anaconda3/envs/EDRE3D/lib/python3.8/site-packages/flask/app.py", line 1825, in full_dispatch_request
    rv = self.handle_user_exception(e)
  File "/home/dcy/anaconda3/envs/EDRE3D/lib/python3.8/site-packages/flask_cors/extension.py", line 165, in wrapped_function
    return cors_after_request(app.make_response(f(*args, **kwargs)))
  File "/home/dcy/anaconda3/envs/EDRE3D/lib/python3.8/site-packages/flask/app.py", line 1823, in full_dispatch_request
    rv = self.dispatch_request()
  File "/home/dcy/anaconda3/envs/EDRE3D/lib/python3.8/site-packages/flask/app.py", line 1799, in dispatch_request
    return self.ensure_sync(self.view_functions[rule.endpoint])(**view_args)
  File "/home/dcy/code/EDREserver/app/api/views.py", line 68, in getAllProjects
    projectList = ProjectList.query.all()
  File "/home/dcy/anaconda3/envs/EDRE3D/lib/python3.8/site-packages/sqlalchemy/orm/query.py", line 2697, in all
    return self._iter().all()  # type: ignore
  File "/home/dcy/anaconda3/envs/EDRE3D/lib/python3.8/site-packages/sqlalchemy/orm/query.py", line 2855, in _iter
    result: Union[ScalarResult[_T], Result[_T]] = self.session.execute(
  File "/home/dcy/anaconda3/envs/EDRE3D/lib/python3.8/site-packages/sqlalchemy/orm/session.py", line 2229, in execute
    return self._execute_internal(
  File "/home/dcy/anaconda3/envs/EDRE3D/lib/python3.8/site-packages/sqlalchemy/orm/session.py", line 2114, in _execute_internal
    conn = self._connection_for_bind(bind)
  File "/home/dcy/anaconda3/envs/EDRE3D/lib/python3.8/site-packages/sqlalchemy/orm/session.py", line 1981, in _connection_for_bind
    return trans._connection_for_bind(engine, execution_options)
  File "<string>", line 2, in _connection_for_bind
  File "/home/dcy/anaconda3/envs/EDRE3D/lib/python3.8/site-packages/sqlalchemy/orm/state_changes.py", line 137, in _go
    ret_value = fn(self, *arg, **kw)
  File "/home/dcy/anaconda3/envs/EDRE3D/lib/python3.8/site-packages/sqlalchemy/orm/session.py", line 1108, in _connection_for_bind
    conn = bind.connect()
  File "/home/dcy/anaconda3/envs/EDRE3D/lib/python3.8/site-packages/sqlalchemy/engine/base.py", line 3251, in connect
    return self._connection_cls(self)
  File "/home/dcy/anaconda3/envs/EDRE3D/lib/python3.8/site-packages/sqlalchemy/engine/base.py", line 147, in __init__
    Connection._handle_dbapi_exception_noconnection(
  File "/home/dcy/anaconda3/envs/EDRE3D/lib/python3.8/site-packages/sqlalchemy/engine/base.py", line 2413, in _handle_dbapi_exception_noconnection
    raise sqlalchemy_exception.with_traceback(exc_info[2]) from e
  File "/home/dcy/anaconda3/envs/EDRE3D/lib/python3.8/site-packages/sqlalchemy/engine/base.py", line 145, in __init__
    self._dbapi_connection = engine.raw_connection()
  File "/home/dcy/anaconda3/envs/EDRE3D/lib/python3.8/site-packages/sqlalchemy/engine/base.py", line 3275, in raw_connection
    return self.pool.connect()
  File "/home/dcy/anaconda3/envs/EDRE3D/lib/python3.8/site-packages/sqlalchemy/pool/base.py", line 455, in connect
    return _ConnectionFairy._checkout(self)
  File "/home/dcy/anaconda3/envs/EDRE3D/lib/python3.8/site-packages/sqlalchemy/pool/base.py", line 1271, in _checkout
    fairy = _ConnectionRecord.checkout(pool)
  File "/home/dcy/anaconda3/envs/EDRE3D/lib/python3.8/site-packages/sqlalchemy/pool/base.py", line 725, in checkout
    rec._checkin_failed(err, _fairy_was_created=False)
  File "/home/dcy/anaconda3/envs/EDRE3D/lib/python3.8/site-packages/sqlalchemy/util/langhelpers.py", line 147, in __exit__
    raise exc_value.with_traceback(exc_tb)
  File "/home/dcy/anaconda3/envs/EDRE3D/lib/python3.8/site-packages/sqlalchemy/pool/base.py", line 722, in checkout
    dbapi_connection = rec.get_connection()
  File "/home/dcy/anaconda3/envs/EDRE3D/lib/python3.8/site-packages/sqlalchemy/pool/base.py", line 842, in get_connection
    self.__connect()
  File "/home/dcy/anaconda3/envs/EDRE3D/lib/python3.8/site-packages/sqlalchemy/pool/base.py", line 906, in __connect
    pool.logger.debug("Error on connect(): %s", e)
  File "/home/dcy/anaconda3/envs/EDRE3D/lib/python3.8/site-packages/sqlalchemy/util/langhelpers.py", line 147, in __exit__
    raise exc_value.with_traceback(exc_tb)
  File "/home/dcy/anaconda3/envs/EDRE3D/lib/python3.8/site-packages/sqlalchemy/pool/base.py", line 901, in __connect
    self.dbapi_connection = connection = pool._invoke_creator(self)
  File "/home/dcy/anaconda3/envs/EDRE3D/lib/python3.8/site-packages/sqlalchemy/engine/create.py", line 636, in connect
    return dialect.connect(*cargs, **cparams)
  File "/home/dcy/anaconda3/envs/EDRE3D/lib/python3.8/site-packages/sqlalchemy/engine/default.py", line 580, in connect
    return self.loaded_dbapi.connect(*cargs, **cparams)
  File "/home/dcy/anaconda3/envs/EDRE3D/lib/python3.8/site-packages/pymysql/connections.py", line 352, in __init__
    self.connect()
  File "/home/dcy/anaconda3/envs/EDRE3D/lib/python3.8/site-packages/pymysql/connections.py", line 668, in connect
    raise exc
sqlalchemy.exc.OperationalError: (pymysql.err.OperationalError) (2003, "Can't connect to MySQL server on '10.162.220.155' (timed out)")
(Background on this error at: https://sqlalche.me/e/20/e3q8)
10.162.135.151 - - [2023-05-03 21:43:25] "GET /api/getAllProjects HTTP/1.1" 500 467 10.008267
[2023-05-03 21:43:35,236] ERROR in app: Exception on /api/getAllProjects [GET]
Traceback (most recent call last):
  File "/home/dcy/anaconda3/envs/EDRE3D/lib/python3.8/site-packages/pymysql/connections.py", line 616, in connect
    sock = socket.create_connection(
  File "/home/dcy/anaconda3/envs/EDRE3D/lib/python3.8/socket.py", line 808, in create_connection
    raise err
  File "/home/dcy/anaconda3/envs/EDRE3D/lib/python3.8/socket.py", line 796, in create_connection
    sock.connect(sa)
socket.timeout: timed out

During handling of the above exception, another exception occurred:

Traceback (most recent call last):
  File "/home/dcy/anaconda3/envs/EDRE3D/lib/python3.8/site-packages/sqlalchemy/engine/base.py", line 145, in __init__
    self._dbapi_connection = engine.raw_connection()
  File "/home/dcy/anaconda3/envs/EDRE3D/lib/python3.8/site-packages/sqlalchemy/engine/base.py", line 3275, in raw_connection
    return self.pool.connect()
  File "/home/dcy/anaconda3/envs/EDRE3D/lib/python3.8/site-packages/sqlalchemy/pool/base.py", line 455, in connect
    return _ConnectionFairy._checkout(self)
  File "/home/dcy/anaconda3/envs/EDRE3D/lib/python3.8/site-packages/sqlalchemy/pool/base.py", line 1271, in _checkout
    fairy = _ConnectionRecord.checkout(pool)
  File "/home/dcy/anaconda3/envs/EDRE3D/lib/python3.8/site-packages/sqlalchemy/pool/base.py", line 725, in checkout
    rec._checkin_failed(err, _fairy_was_created=False)
  File "/home/dcy/anaconda3/envs/EDRE3D/lib/python3.8/site-packages/sqlalchemy/util/langhelpers.py", line 147, in __exit__
    raise exc_value.with_traceback(exc_tb)
  File "/home/dcy/anaconda3/envs/EDRE3D/lib/python3.8/site-packages/sqlalchemy/pool/base.py", line 722, in checkout
    dbapi_connection = rec.get_connection()
  File "/home/dcy/anaconda3/envs/EDRE3D/lib/python3.8/site-packages/sqlalchemy/pool/base.py", line 842, in get_connection
    self.__connect()
  File "/home/dcy/anaconda3/envs/EDRE3D/lib/python3.8/site-packages/sqlalchemy/pool/base.py", line 906, in __connect
    pool.logger.debug("Error on connect(): %s", e)
  File "/home/dcy/anaconda3/envs/EDRE3D/lib/python3.8/site-packages/sqlalchemy/util/langhelpers.py", line 147, in __exit__
    raise exc_value.with_traceback(exc_tb)
  File "/home/dcy/anaconda3/envs/EDRE3D/lib/python3.8/site-packages/sqlalchemy/pool/base.py", line 901, in __connect
    self.dbapi_connection = connection = pool._invoke_creator(self)
  File "/home/dcy/anaconda3/envs/EDRE3D/lib/python3.8/site-packages/sqlalchemy/engine/create.py", line 636, in connect
    return dialect.connect(*cargs, **cparams)
  File "/home/dcy/anaconda3/envs/EDRE3D/lib/python3.8/site-packages/sqlalchemy/engine/default.py", line 580, in connect
    return self.loaded_dbapi.connect(*cargs, **cparams)
  File "/home/dcy/anaconda3/envs/EDRE3D/lib/python3.8/site-packages/pymysql/connections.py", line 352, in __init__
    self.connect()
  File "/home/dcy/anaconda3/envs/EDRE3D/lib/python3.8/site-packages/pymysql/connections.py", line 668, in connect
    raise exc
pymysql.err.OperationalError: (2003, "Can't connect to MySQL server on '10.162.220.155' (timed out)")

The above exception was the direct cause of the following exception:

Traceback (most recent call last):
  File "/home/dcy/anaconda3/envs/EDRE3D/lib/python3.8/site-packages/flask/app.py", line 2528, in wsgi_app
    response = self.full_dispatch_request()
  File "/home/dcy/anaconda3/envs/EDRE3D/lib/python3.8/site-packages/flask/app.py", line 1825, in full_dispatch_request
    rv = self.handle_user_exception(e)
  File "/home/dcy/anaconda3/envs/EDRE3D/lib/python3.8/site-packages/flask_cors/extension.py", line 165, in wrapped_function
    return cors_after_request(app.make_response(f(*args, **kwargs)))
  File "/home/dcy/anaconda3/envs/EDRE3D/lib/python3.8/site-packages/flask/app.py", line 1823, in full_dispatch_request
    rv = self.dispatch_request()
  File "/home/dcy/anaconda3/envs/EDRE3D/lib/python3.8/site-packages/flask/app.py", line 1799, in dispatch_request
    return self.ensure_sync(self.view_functions[rule.endpoint])(**view_args)
  File "/home/dcy/code/EDREserver/app/api/views.py", line 68, in getAllProjects
    projectList = ProjectList.query.all()
  File "/home/dcy/anaconda3/envs/EDRE3D/lib/python3.8/site-packages/sqlalchemy/orm/query.py", line 2697, in all
    return self._iter().all()  # type: ignore
  File "/home/dcy/anaconda3/envs/EDRE3D/lib/python3.8/site-packages/sqlalchemy/orm/query.py", line 2855, in _iter
    result: Union[ScalarResult[_T], Result[_T]] = self.session.execute(
  File "/home/dcy/anaconda3/envs/EDRE3D/lib/python3.8/site-packages/sqlalchemy/orm/session.py", line 2229, in execute
    return self._execute_internal(
  File "/home/dcy/anaconda3/envs/EDRE3D/lib/python3.8/site-packages/sqlalchemy/orm/session.py", line 2114, in _execute_internal
    conn = self._connection_for_bind(bind)
  File "/home/dcy/anaconda3/envs/EDRE3D/lib/python3.8/site-packages/sqlalchemy/orm/session.py", line 1981, in _connection_for_bind
    return trans._connection_for_bind(engine, execution_options)
  File "<string>", line 2, in _connection_for_bind
  File "/home/dcy/anaconda3/envs/EDRE3D/lib/python3.8/site-packages/sqlalchemy/orm/state_changes.py", line 137, in _go
    ret_value = fn(self, *arg, **kw)
  File "/home/dcy/anaconda3/envs/EDRE3D/lib/python3.8/site-packages/sqlalchemy/orm/session.py", line 1108, in _connection_for_bind
    conn = bind.connect()
  File "/home/dcy/anaconda3/envs/EDRE3D/lib/python3.8/site-packages/sqlalchemy/engine/base.py", line 3251, in connect
    return self._connection_cls(self)
  File "/home/dcy/anaconda3/envs/EDRE3D/lib/python3.8/site-packages/sqlalchemy/engine/base.py", line 147, in __init__
    Connection._handle_dbapi_exception_noconnection(
  File "/home/dcy/anaconda3/envs/EDRE3D/lib/python3.8/site-packages/sqlalchemy/engine/base.py", line 2413, in _handle_dbapi_exception_noconnection
    raise sqlalchemy_exception.with_traceback(exc_info[2]) from e
  File "/home/dcy/anaconda3/envs/EDRE3D/lib/python3.8/site-packages/sqlalchemy/engine/base.py", line 145, in __init__
    self._dbapi_connection = engine.raw_connection()
  File "/home/dcy/anaconda3/envs/EDRE3D/lib/python3.8/site-packages/sqlalchemy/engine/base.py", line 3275, in raw_connection
    return self.pool.connect()
  File "/home/dcy/anaconda3/envs/EDRE3D/lib/python3.8/site-packages/sqlalchemy/pool/base.py", line 455, in connect
    return _ConnectionFairy._checkout(self)
  File "/home/dcy/anaconda3/envs/EDRE3D/lib/python3.8/site-packages/sqlalchemy/pool/base.py", line 1271, in _checkout
    fairy = _ConnectionRecord.checkout(pool)
  File "/home/dcy/anaconda3/envs/EDRE3D/lib/python3.8/site-packages/sqlalchemy/pool/base.py", line 725, in checkout
    rec._checkin_failed(err, _fairy_was_created=False)
  File "/home/dcy/anaconda3/envs/EDRE3D/lib/python3.8/site-packages/sqlalchemy/util/langhelpers.py", line 147, in __exit__
    raise exc_value.with_traceback(exc_tb)
  File "/home/dcy/anaconda3/envs/EDRE3D/lib/python3.8/site-packages/sqlalchemy/pool/base.py", line 722, in checkout
    dbapi_connection = rec.get_connection()
  File "/home/dcy/anaconda3/envs/EDRE3D/lib/python3.8/site-packages/sqlalchemy/pool/base.py", line 842, in get_connection
    self.__connect()
  File "/home/dcy/anaconda3/envs/EDRE3D/lib/python3.8/site-packages/sqlalchemy/pool/base.py", line 906, in __connect
    pool.logger.debug("Error on connect(): %s", e)
  File "/home/dcy/anaconda3/envs/EDRE3D/lib/python3.8/site-packages/sqlalchemy/util/langhelpers.py", line 147, in __exit__
    raise exc_value.with_traceback(exc_tb)
  File "/home/dcy/anaconda3/envs/EDRE3D/lib/python3.8/site-packages/sqlalchemy/pool/base.py", line 901, in __connect
    self.dbapi_connection = connection = pool._invoke_creator(self)
  File "/home/dcy/anaconda3/envs/EDRE3D/lib/python3.8/site-packages/sqlalchemy/engine/create.py", line 636, in connect
    return dialect.connect(*cargs, **cparams)
  File "/home/dcy/anaconda3/envs/EDRE3D/lib/python3.8/site-packages/sqlalchemy/engine/default.py", line 580, in connect
    return self.loaded_dbapi.connect(*cargs, **cparams)
  File "/home/dcy/anaconda3/envs/EDRE3D/lib/python3.8/site-packages/pymysql/connections.py", line 352, in __init__
    self.connect()
  File "/home/dcy/anaconda3/envs/EDRE3D/lib/python3.8/site-packages/pymysql/connections.py", line 668, in connect
    raise exc
sqlalchemy.exc.OperationalError: (pymysql.err.OperationalError) (2003, "Can't connect to MySQL server on '10.162.220.155' (timed out)")
(Background on this error at: https://sqlalche.me/e/20/e3q8)
10.162.135.151 - - [2023-05-03 21:43:35] "GET /api/getAllProjects HTTP/1.1" 500 467 10.005883
[2023-05-03 21:43:45,245] ERROR in app: Exception on /api/getAllProjects [GET]
Traceback (most recent call last):
  File "/home/dcy/anaconda3/envs/EDRE3D/lib/python3.8/site-packages/pymysql/connections.py", line 616, in connect
    sock = socket.create_connection(
  File "/home/dcy/anaconda3/envs/EDRE3D/lib/python3.8/socket.py", line 808, in create_connection
    raise err
  File "/home/dcy/anaconda3/envs/EDRE3D/lib/python3.8/socket.py", line 796, in create_connection
    sock.connect(sa)
socket.timeout: timed out

During handling of the above exception, another exception occurred:

Traceback (most recent call last):
  File "/home/dcy/anaconda3/envs/EDRE3D/lib/python3.8/site-packages/sqlalchemy/engine/base.py", line 145, in __init__
    self._dbapi_connection = engine.raw_connection()
  File "/home/dcy/anaconda3/envs/EDRE3D/lib/python3.8/site-packages/sqlalchemy/engine/base.py", line 3275, in raw_connection
    return self.pool.connect()
  File "/home/dcy/anaconda3/envs/EDRE3D/lib/python3.8/site-packages/sqlalchemy/pool/base.py", line 455, in connect
    return _ConnectionFairy._checkout(self)
  File "/home/dcy/anaconda3/envs/EDRE3D/lib/python3.8/site-packages/sqlalchemy/pool/base.py", line 1271, in _checkout
    fairy = _ConnectionRecord.checkout(pool)
  File "/home/dcy/anaconda3/envs/EDRE3D/lib/python3.8/site-packages/sqlalchemy/pool/base.py", line 725, in checkout
    rec._checkin_failed(err, _fairy_was_created=False)
  File "/home/dcy/anaconda3/envs/EDRE3D/lib/python3.8/site-packages/sqlalchemy/util/langhelpers.py", line 147, in __exit__
    raise exc_value.with_traceback(exc_tb)
  File "/home/dcy/anaconda3/envs/EDRE3D/lib/python3.8/site-packages/sqlalchemy/pool/base.py", line 722, in checkout
    dbapi_connection = rec.get_connection()
  File "/home/dcy/anaconda3/envs/EDRE3D/lib/python3.8/site-packages/sqlalchemy/pool/base.py", line 842, in get_connection
    self.__connect()
  File "/home/dcy/anaconda3/envs/EDRE3D/lib/python3.8/site-packages/sqlalchemy/pool/base.py", line 906, in __connect
    pool.logger.debug("Error on connect(): %s", e)
  File "/home/dcy/anaconda3/envs/EDRE3D/lib/python3.8/site-packages/sqlalchemy/util/langhelpers.py", line 147, in __exit__
    raise exc_value.with_traceback(exc_tb)
  File "/home/dcy/anaconda3/envs/EDRE3D/lib/python3.8/site-packages/sqlalchemy/pool/base.py", line 901, in __connect
    self.dbapi_connection = connection = pool._invoke_creator(self)
  File "/home/dcy/anaconda3/envs/EDRE3D/lib/python3.8/site-packages/sqlalchemy/engine/create.py", line 636, in connect
    return dialect.connect(*cargs, **cparams)
  File "/home/dcy/anaconda3/envs/EDRE3D/lib/python3.8/site-packages/sqlalchemy/engine/default.py", line 580, in connect
    return self.loaded_dbapi.connect(*cargs, **cparams)
  File "/home/dcy/anaconda3/envs/EDRE3D/lib/python3.8/site-packages/pymysql/connections.py", line 352, in __init__
    self.connect()
  File "/home/dcy/anaconda3/envs/EDRE3D/lib/python3.8/site-packages/pymysql/connections.py", line 668, in connect
    raise exc
pymysql.err.OperationalError: (2003, "Can't connect to MySQL server on '10.162.220.155' (timed out)")

The above exception was the direct cause of the following exception:

Traceback (most recent call last):
  File "/home/dcy/anaconda3/envs/EDRE3D/lib/python3.8/site-packages/flask/app.py", line 2528, in wsgi_app
    response = self.full_dispatch_request()
  File "/home/dcy/anaconda3/envs/EDRE3D/lib/python3.8/site-packages/flask/app.py", line 1825, in full_dispatch_request
    rv = self.handle_user_exception(e)
  File "/home/dcy/anaconda3/envs/EDRE3D/lib/python3.8/site-packages/flask_cors/extension.py", line 165, in wrapped_function
    return cors_after_request(app.make_response(f(*args, **kwargs)))
  File "/home/dcy/anaconda3/envs/EDRE3D/lib/python3.8/site-packages/flask/app.py", line 1823, in full_dispatch_request
    rv = self.dispatch_request()
  File "/home/dcy/anaconda3/envs/EDRE3D/lib/python3.8/site-packages/flask/app.py", line 1799, in dispatch_request
    return self.ensure_sync(self.view_functions[rule.endpoint])(**view_args)
  File "/home/dcy/code/EDREserver/app/api/views.py", line 68, in getAllProjects
    projectList = ProjectList.query.all()
  File "/home/dcy/anaconda3/envs/EDRE3D/lib/python3.8/site-packages/sqlalchemy/orm/query.py", line 2697, in all
    return self._iter().all()  # type: ignore
  File "/home/dcy/anaconda3/envs/EDRE3D/lib/python3.8/site-packages/sqlalchemy/orm/query.py", line 2855, in _iter
    result: Union[ScalarResult[_T], Result[_T]] = self.session.execute(
  File "/home/dcy/anaconda3/envs/EDRE3D/lib/python3.8/site-packages/sqlalchemy/orm/session.py", line 2229, in execute
    return self._execute_internal(
  File "/home/dcy/anaconda3/envs/EDRE3D/lib/python3.8/site-packages/sqlalchemy/orm/session.py", line 2114, in _execute_internal
    conn = self._connection_for_bind(bind)
  File "/home/dcy/anaconda3/envs/EDRE3D/lib/python3.8/site-packages/sqlalchemy/orm/session.py", line 1981, in _connection_for_bind
    return trans._connection_for_bind(engine, execution_options)
  File "<string>", line 2, in _connection_for_bind
  File "/home/dcy/anaconda3/envs/EDRE3D/lib/python3.8/site-packages/sqlalchemy/orm/state_changes.py", line 137, in _go
    ret_value = fn(self, *arg, **kw)
  File "/home/dcy/anaconda3/envs/EDRE3D/lib/python3.8/site-packages/sqlalchemy/orm/session.py", line 1108, in _connection_for_bind
    conn = bind.connect()
  File "/home/dcy/anaconda3/envs/EDRE3D/lib/python3.8/site-packages/sqlalchemy/engine/base.py", line 3251, in connect
    return self._connection_cls(self)
  File "/home/dcy/anaconda3/envs/EDRE3D/lib/python3.8/site-packages/sqlalchemy/engine/base.py", line 147, in __init__
    Connection._handle_dbapi_exception_noconnection(
  File "/home/dcy/anaconda3/envs/EDRE3D/lib/python3.8/site-packages/sqlalchemy/engine/base.py", line 2413, in _handle_dbapi_exception_noconnection
    raise sqlalchemy_exception.with_traceback(exc_info[2]) from e
  File "/home/dcy/anaconda3/envs/EDRE3D/lib/python3.8/site-packages/sqlalchemy/engine/base.py", line 145, in __init__
    self._dbapi_connection = engine.raw_connection()
  File "/home/dcy/anaconda3/envs/EDRE3D/lib/python3.8/site-packages/sqlalchemy/engine/base.py", line 3275, in raw_connection
    return self.pool.connect()
  File "/home/dcy/anaconda3/envs/EDRE3D/lib/python3.8/site-packages/sqlalchemy/pool/base.py", line 455, in connect
    return _ConnectionFairy._checkout(self)
  File "/home/dcy/anaconda3/envs/EDRE3D/lib/python3.8/site-packages/sqlalchemy/pool/base.py", line 1271, in _checkout
    fairy = _ConnectionRecord.checkout(pool)
  File "/home/dcy/anaconda3/envs/EDRE3D/lib/python3.8/site-packages/sqlalchemy/pool/base.py", line 725, in checkout
    rec._checkin_failed(err, _fairy_was_created=False)
  File "/home/dcy/anaconda3/envs/EDRE3D/lib/python3.8/site-packages/sqlalchemy/util/langhelpers.py", line 147, in __exit__
    raise exc_value.with_traceback(exc_tb)
  File "/home/dcy/anaconda3/envs/EDRE3D/lib/python3.8/site-packages/sqlalchemy/pool/base.py", line 722, in checkout
    dbapi_connection = rec.get_connection()
  File "/home/dcy/anaconda3/envs/EDRE3D/lib/python3.8/site-packages/sqlalchemy/pool/base.py", line 842, in get_connection
    self.__connect()
  File "/home/dcy/anaconda3/envs/EDRE3D/lib/python3.8/site-packages/sqlalchemy/pool/base.py", line 906, in __connect
    pool.logger.debug("Error on connect(): %s", e)
  File "/home/dcy/anaconda3/envs/EDRE3D/lib/python3.8/site-packages/sqlalchemy/util/langhelpers.py", line 147, in __exit__
    raise exc_value.with_traceback(exc_tb)
  File "/home/dcy/anaconda3/envs/EDRE3D/lib/python3.8/site-packages/sqlalchemy/pool/base.py", line 901, in __connect
    self.dbapi_connection = connection = pool._invoke_creator(self)
  File "/home/dcy/anaconda3/envs/EDRE3D/lib/python3.8/site-packages/sqlalchemy/engine/create.py", line 636, in connect
    return dialect.connect(*cargs, **cparams)
  File "/home/dcy/anaconda3/envs/EDRE3D/lib/python3.8/site-packages/sqlalchemy/engine/default.py", line 580, in connect
    return self.loaded_dbapi.connect(*cargs, **cparams)
  File "/home/dcy/anaconda3/envs/EDRE3D/lib/python3.8/site-packages/pymysql/connections.py", line 352, in __init__
    self.connect()
  File "/home/dcy/anaconda3/envs/EDRE3D/lib/python3.8/site-packages/pymysql/connections.py", line 668, in connect
    raise exc
sqlalchemy.exc.OperationalError: (pymysql.err.OperationalError) (2003, "Can't connect to MySQL server on '10.162.220.155' (timed out)")
(Background on this error at: https://sqlalche.me/e/20/e3q8)
10.162.135.151 - - [2023-05-03 21:43:45] "GET /api/getAllProjects HTTP/1.1" 500 467 10.009278
[2023-05-03 21:43:55,253] ERROR in app: Exception on /api/getAllProjects [GET]
Traceback (most recent call last):
  File "/home/dcy/anaconda3/envs/EDRE3D/lib/python3.8/site-packages/pymysql/connections.py", line 616, in connect
    sock = socket.create_connection(
  File "/home/dcy/anaconda3/envs/EDRE3D/lib/python3.8/socket.py", line 808, in create_connection
    raise err
  File "/home/dcy/anaconda3/envs/EDRE3D/lib/python3.8/socket.py", line 796, in create_connection
    sock.connect(sa)
socket.timeout: timed out

During handling of the above exception, another exception occurred:

Traceback (most recent call last):
  File "/home/dcy/anaconda3/envs/EDRE3D/lib/python3.8/site-packages/sqlalchemy/engine/base.py", line 145, in __init__
    self._dbapi_connection = engine.raw_connection()
  File "/home/dcy/anaconda3/envs/EDRE3D/lib/python3.8/site-packages/sqlalchemy/engine/base.py", line 3275, in raw_connection
    return self.pool.connect()
  File "/home/dcy/anaconda3/envs/EDRE3D/lib/python3.8/site-packages/sqlalchemy/pool/base.py", line 455, in connect
    return _ConnectionFairy._checkout(self)
  File "/home/dcy/anaconda3/envs/EDRE3D/lib/python3.8/site-packages/sqlalchemy/pool/base.py", line 1271, in _checkout
    fairy = _ConnectionRecord.checkout(pool)
  File "/home/dcy/anaconda3/envs/EDRE3D/lib/python3.8/site-packages/sqlalchemy/pool/base.py", line 725, in checkout
    rec._checkin_failed(err, _fairy_was_created=False)
  File "/home/dcy/anaconda3/envs/EDRE3D/lib/python3.8/site-packages/sqlalchemy/util/langhelpers.py", line 147, in __exit__
    raise exc_value.with_traceback(exc_tb)
  File "/home/dcy/anaconda3/envs/EDRE3D/lib/python3.8/site-packages/sqlalchemy/pool/base.py", line 722, in checkout
    dbapi_connection = rec.get_connection()
  File "/home/dcy/anaconda3/envs/EDRE3D/lib/python3.8/site-packages/sqlalchemy/pool/base.py", line 842, in get_connection
    self.__connect()
  File "/home/dcy/anaconda3/envs/EDRE3D/lib/python3.8/site-packages/sqlalchemy/pool/base.py", line 906, in __connect
    pool.logger.debug("Error on connect(): %s", e)
  File "/home/dcy/anaconda3/envs/EDRE3D/lib/python3.8/site-packages/sqlalchemy/util/langhelpers.py", line 147, in __exit__
    raise exc_value.with_traceback(exc_tb)
  File "/home/dcy/anaconda3/envs/EDRE3D/lib/python3.8/site-packages/sqlalchemy/pool/base.py", line 901, in __connect
    self.dbapi_connection = connection = pool._invoke_creator(self)
  File "/home/dcy/anaconda3/envs/EDRE3D/lib/python3.8/site-packages/sqlalchemy/engine/create.py", line 636, in connect
    return dialect.connect(*cargs, **cparams)
  File "/home/dcy/anaconda3/envs/EDRE3D/lib/python3.8/site-packages/sqlalchemy/engine/default.py", line 580, in connect
    return self.loaded_dbapi.connect(*cargs, **cparams)
  File "/home/dcy/anaconda3/envs/EDRE3D/lib/python3.8/site-packages/pymysql/connections.py", line 352, in __init__
    self.connect()
  File "/home/dcy/anaconda3/envs/EDRE3D/lib/python3.8/site-packages/pymysql/connections.py", line 668, in connect
    raise exc
pymysql.err.OperationalError: (2003, "Can't connect to MySQL server on '10.162.220.155' (timed out)")

The above exception was the direct cause of the following exception:

Traceback (most recent call last):
  File "/home/dcy/anaconda3/envs/EDRE3D/lib/python3.8/site-packages/flask/app.py", line 2528, in wsgi_app
    response = self.full_dispatch_request()
  File "/home/dcy/anaconda3/envs/EDRE3D/lib/python3.8/site-packages/flask/app.py", line 1825, in full_dispatch_request
    rv = self.handle_user_exception(e)
  File "/home/dcy/anaconda3/envs/EDRE3D/lib/python3.8/site-packages/flask_cors/extension.py", line 165, in wrapped_function
    return cors_after_request(app.make_response(f(*args, **kwargs)))
  File "/home/dcy/anaconda3/envs/EDRE3D/lib/python3.8/site-packages/flask/app.py", line 1823, in full_dispatch_request
    rv = self.dispatch_request()
  File "/home/dcy/anaconda3/envs/EDRE3D/lib/python3.8/site-packages/flask/app.py", line 1799, in dispatch_request
    return self.ensure_sync(self.view_functions[rule.endpoint])(**view_args)
  File "/home/dcy/code/EDREserver/app/api/views.py", line 68, in getAllProjects
    projectList = ProjectList.query.all()
  File "/home/dcy/anaconda3/envs/EDRE3D/lib/python3.8/site-packages/sqlalchemy/orm/query.py", line 2697, in all
    return self._iter().all()  # type: ignore
  File "/home/dcy/anaconda3/envs/EDRE3D/lib/python3.8/site-packages/sqlalchemy/orm/query.py", line 2855, in _iter
    result: Union[ScalarResult[_T], Result[_T]] = self.session.execute(
  File "/home/dcy/anaconda3/envs/EDRE3D/lib/python3.8/site-packages/sqlalchemy/orm/session.py", line 2229, in execute
    return self._execute_internal(
  File "/home/dcy/anaconda3/envs/EDRE3D/lib/python3.8/site-packages/sqlalchemy/orm/session.py", line 2114, in _execute_internal
    conn = self._connection_for_bind(bind)
  File "/home/dcy/anaconda3/envs/EDRE3D/lib/python3.8/site-packages/sqlalchemy/orm/session.py", line 1981, in _connection_for_bind
    return trans._connection_for_bind(engine, execution_options)
  File "<string>", line 2, in _connection_for_bind
  File "/home/dcy/anaconda3/envs/EDRE3D/lib/python3.8/site-packages/sqlalchemy/orm/state_changes.py", line 137, in _go
    ret_value = fn(self, *arg, **kw)
  File "/home/dcy/anaconda3/envs/EDRE3D/lib/python3.8/site-packages/sqlalchemy/orm/session.py", line 1108, in _connection_for_bind
    conn = bind.connect()
  File "/home/dcy/anaconda3/envs/EDRE3D/lib/python3.8/site-packages/sqlalchemy/engine/base.py", line 3251, in connect
    return self._connection_cls(self)
  File "/home/dcy/anaconda3/envs/EDRE3D/lib/python3.8/site-packages/sqlalchemy/engine/base.py", line 147, in __init__
    Connection._handle_dbapi_exception_noconnection(
  File "/home/dcy/anaconda3/envs/EDRE3D/lib/python3.8/site-packages/sqlalchemy/engine/base.py", line 2413, in _handle_dbapi_exception_noconnection
    raise sqlalchemy_exception.with_traceback(exc_info[2]) from e
  File "/home/dcy/anaconda3/envs/EDRE3D/lib/python3.8/site-packages/sqlalchemy/engine/base.py", line 145, in __init__
    self._dbapi_connection = engine.raw_connection()
  File "/home/dcy/anaconda3/envs/EDRE3D/lib/python3.8/site-packages/sqlalchemy/engine/base.py", line 3275, in raw_connection
    return self.pool.connect()
  File "/home/dcy/anaconda3/envs/EDRE3D/lib/python3.8/site-packages/sqlalchemy/pool/base.py", line 455, in connect
    return _ConnectionFairy._checkout(self)
  File "/home/dcy/anaconda3/envs/EDRE3D/lib/python3.8/site-packages/sqlalchemy/pool/base.py", line 1271, in _checkout
    fairy = _ConnectionRecord.checkout(pool)
  File "/home/dcy/anaconda3/envs/EDRE3D/lib/python3.8/site-packages/sqlalchemy/pool/base.py", line 725, in checkout
    rec._checkin_failed(err, _fairy_was_created=False)
  File "/home/dcy/anaconda3/envs/EDRE3D/lib/python3.8/site-packages/sqlalchemy/util/langhelpers.py", line 147, in __exit__
    raise exc_value.with_traceback(exc_tb)
  File "/home/dcy/anaconda3/envs/EDRE3D/lib/python3.8/site-packages/sqlalchemy/pool/base.py", line 722, in checkout
    dbapi_connection = rec.get_connection()
  File "/home/dcy/anaconda3/envs/EDRE3D/lib/python3.8/site-packages/sqlalchemy/pool/base.py", line 842, in get_connection
    self.__connect()
  File "/home/dcy/anaconda3/envs/EDRE3D/lib/python3.8/site-packages/sqlalchemy/pool/base.py", line 906, in __connect
    pool.logger.debug("Error on connect(): %s", e)
  File "/home/dcy/anaconda3/envs/EDRE3D/lib/python3.8/site-packages/sqlalchemy/util/langhelpers.py", line 147, in __exit__
    raise exc_value.with_traceback(exc_tb)
  File "/home/dcy/anaconda3/envs/EDRE3D/lib/python3.8/site-packages/sqlalchemy/pool/base.py", line 901, in __connect
    self.dbapi_connection = connection = pool._invoke_creator(self)
  File "/home/dcy/anaconda3/envs/EDRE3D/lib/python3.8/site-packages/sqlalchemy/engine/create.py", line 636, in connect
    return dialect.connect(*cargs, **cparams)
  File "/home/dcy/anaconda3/envs/EDRE3D/lib/python3.8/site-packages/sqlalchemy/engine/default.py", line 580, in connect
    return self.loaded_dbapi.connect(*cargs, **cparams)
  File "/home/dcy/anaconda3/envs/EDRE3D/lib/python3.8/site-packages/pymysql/connections.py", line 352, in __init__
    self.connect()
  File "/home/dcy/anaconda3/envs/EDRE3D/lib/python3.8/site-packages/pymysql/connections.py", line 668, in connect
    raise exc
sqlalchemy.exc.OperationalError: (pymysql.err.OperationalError) (2003, "Can't connect to MySQL server on '10.162.220.155' (timed out)")
(Background on this error at: https://sqlalche.me/e/20/e3q8)
